<?xml version="1.0"?>
<robot name="ObjectCableSystem">

  <link name="base_link">
    <inertial>
      <mass value="0.0001"/>
      <origin xyz="0.0 0.0 0.0"/>
      <inertia ixx="1e-10" ixy="0." ixz="0." iyy="1e-10" iyz="0." izz="1e-10"/>
    </inertial>
  </link>

  <link name="base_x_link">
    <inertial>
      <mass value="0.0001"/>
      <origin xyz="0.0 0.0 0.0"/>
      <inertia ixx="1e-10" ixy="0." ixz="0." iyy="1e-10" iyz="0." izz="1e-10"/>
    </inertial>
  </link>

  <link name="base_y_link">
    <inertial>
      <mass value="0.0001"/>
      <origin xyz="0.0 0.0 0.0"/>
      <inertia ixx="1e-10" ixy="0." ixz="0." iyy="1e-10" iyz="0." izz="1e-10"/>
    </inertial>
  </link>

  <link name="end_effector_link">
    <inertial>
      <mass value="0.0001"/>
      <origin xyz="0.0 0.0 0.0"/>
      <inertia ixx="1e-10" ixy="0." ixz="0." iyy="1e-10" iyz="0." izz="1e-10"/>
    </inertial>
        <visual>
      <origin rpy="0 0 0" xyz="0 0 0"/>
      <geometry>
        <mesh filename="mesh/end_effector.obj"/>
      </geometry>
    </visual>
  </link>

  <link name="cable_x_link">
    <inertial>
      <mass value="0.0001"/>
      <origin xyz="0.0 0.0 0.0"/>
      <inertia ixx="1e-10" ixy="0." ixz="0." iyy="1e-10" iyz="0." izz="1e-10"/>
    </inertial>
  </link>

  <link name="cable_y_link">
    <inertial>
      <mass value="0.0001"/>
      <origin xyz="0.0 0.0 0.0"/>
      <inertia ixx="1e-10" ixy="0." ixz="0." iyy="1e-10" iyz="0." izz="1e-10"/>
    </inertial>
  </link>

  <link name="cable_z_link">
    <inertial>
      <mass value="0.0001"/>
      <origin xyz="0.0 0.0 0.0"/>
      <inertia ixx="1e-10" ixy="0." ixz="0." iyy="1e-10" iyz="0." izz="1e-10"/>
    </inertial>
  </link>

  <link name="object">
    <inertial>
      <mass value="1.04"/>
      <!-- <mass value="1.80"/> -->
      <origin xyz="0.0 -0.15 0.29"/>
      <inertia ixx="0.21" ixy="0." ixz="0." iyy="0.20" iyz="-0.05" izz="0.09"/>
    </inertial>

    <contact>
      <lateral_friction value="100"/>
      <!-- <rolling_friction value="0.001"/> -->
      <!-- <stiffness value="30000"/> -->
      <!-- <damping value="1000"/> -->
    </contact>

    <visual>
      <origin rpy="0 0 0" xyz="0 0 0"/>
      <geometry>
        <mesh filename="mesh/large_cone.obj"/>
      </geometry>
    </visual>

    <collision>
      <origin rpy="0 0 0" xyz="0 0 0"/>
      <geometry>
        <mesh filename="mesh/large_cone_vhacd.obj"/>
      </geometry>
    </collision>

  </link>

  <!-- active joints for moving the end-effector -->

  <joint name="joint_base_x" type="prismatic">
    <axis xyz="1 0 0"/>
    <parent link="base_link"/>
    <child link="base_x_link"/>
    <limit lower="-100" upper="100"/>
  </joint>

  <joint name="joint_base_y" type="prismatic">
    <axis xyz="0 1 0"/>
    <parent link="base_x_link"/>
    <child link="base_y_link"/>
    <limit lower="-100" upper="100"/>
  </joint>

  <joint name="joint_base_z" type="prismatic">
    <axis xyz="0 0 1"/>
    <parent link="base_y_link"/>
    <child link="end_effector_link"/>
    <limit lower="0." upper="100"/>
  </joint>

  <!-- passive joints equivalent to a cable -->

  <joint name="joint_cable_x" type="revolute">
    <axis xyz="1 0 0"/>
    <parent link="end_effector_link"/>
    <child link="cable_x_link"/>
    <limit lower="-3.14" upper="3.14"/>
  </joint>

  <joint name="joint_cable_y" type="revolute">
    <axis xyz="0 1 0"/>
    <parent link="cable_x_link"/>
    <child link="cable_y_link"/>
    <limit lower="-3.14" upper="3.14"/>
  </joint>

  <joint name="joint_cable_z" type="revolute">
    <axis xyz="0 0 1"/>
    <parent link="cable_y_link"/>
    <child link="cable_z_link"/>
    <limit lower="-3.14" upper="3.14"/>
  </joint>

  <joint name="joint_cable_tether" type="prismatic">
    <origin xyz="0 0.3 -1.5"/>
    <axis xyz="0 0 1"/>
    <parent link="cable_z_link"/>
    <child link="object"/>
    <limit lower="-1.0" upper="1.0"/>
  </joint>

</robot>
